[2025-05-22 14:53:03] [INFO] try to connect LSIS client => 192.168.0.198:2004
[2025-05-22 14:53:08] [INFO] try to connect LSIS client => 192.168.0.198:2004
[2025-05-22 14:53:13] [INFO] try to connect LSIS client => 192.168.0.198:2004
[2025-05-22 14:53:18] [INFO] try to connect LSIS client => 192.168.0.198:2004
[2025-05-22 14:53:23] [INFO] try to connect LSIS client => 192.168.0.198:2004
[2025-05-22 14:53:24] [ERROR] tcp_client_servive : LSIS_ Error: [Connection] Failed to connect to 192.168.0.198:2004
[2025-05-22 14:53:24] [ERROR] 🚨 [ERROR] tcp_client_servive()에서 예외 발생 🚨
📌 파일: D:\project\projects\jais\py_backend\utils\logger.py, 라인: 67
📍 오류 메시지: cannot access local variable 'now' where it is not associated with a value
Traceback (most recent call last):
  File "D:\project\projects\jais\py_backend\utils\protocol\LSIS\client\tcp.py", line 83, in connect
    self.socket = socket.create_connection(
                  ^^^^^^^^^^^^^^^^^^^^^^^^^
  File "C:\Python\Python312\Lib\socket.py", line 865, in create_connection
    raise exceptions[0]
  File "C:\Python\Python312\Lib\socket.py", line 850, in create_connection
    sock.connect(sa)
TimeoutError: [WinError 10060] 연결된 구성원으로부터 응답이 없어 연결하지 못했거나, 호스트로부터 응답이 없어 연결이 끊어졌습니다

During handling of the above exception, another exception occurred:

Traceback (most recent call last):
  File "D:\project/projects/jais/py_backend\LSISsocket\service.py", line 32, in tcp_client_servive
    connect_sock.connect(retry_forever=False)
  File "D:\project\projects\jais\py_backend\utils\protocol\LSIS\client\tcp.py", line 100, in connect
    raise ConnectionException(
utils.protocol.LSIS.exceptions.ConnectionException: LSIS_ Error: [Connection] Failed to connect to 192.168.0.198:2004

During handling of the above exception, another exception occurred:

Traceback (most recent call last):
  File "D:\project\projects\jais\py_backend\utils\logger.py", line 67, in wrapper
    return func(*args, **kwargs)
           ^^^^^^^^^^^^^^^^^^^^^
  File "D:\project/projects/jais/py_backend\LSISsocket\service.py", line 104, in tcp_client_servive
    updated_at=now
               ^^^
UnboundLocalError: cannot access local variable 'now' where it is not associated with a value
[2025-05-22 14:53:28] [INFO] try to connect LSIS client => 192.168.0.198:2004
[2025-05-22 14:53:29] [ERROR] tcp_client_servive : LSIS_ Error: [Connection] Failed to connect to 192.168.0.198:2004
[2025-05-22 14:53:29] [ERROR] 🚨 [ERROR] tcp_client_servive()에서 예외 발생 🚨
📌 파일: D:\project\projects\jais\py_backend\utils\logger.py, 라인: 67
📍 오류 메시지: cannot access local variable 'now' where it is not associated with a value
Traceback (most recent call last):
  File "D:\project\projects\jais\py_backend\utils\protocol\LSIS\client\tcp.py", line 83, in connect
    self.socket = socket.create_connection(
                  ^^^^^^^^^^^^^^^^^^^^^^^^^
  File "C:\Python\Python312\Lib\socket.py", line 865, in create_connection
    raise exceptions[0]
  File "C:\Python\Python312\Lib\socket.py", line 850, in create_connection
    sock.connect(sa)
TimeoutError: [WinError 10060] 연결된 구성원으로부터 응답이 없어 연결하지 못했거나, 호스트로부터 응답이 없어 연결이 끊어졌습니다

During handling of the above exception, another exception occurred:

Traceback (most recent call last):
  File "D:\project/projects/jais/py_backend\LSISsocket\service.py", line 32, in tcp_client_servive
    connect_sock.connect(retry_forever=False)
  File "D:\project\projects\jais\py_backend\utils\protocol\LSIS\client\tcp.py", line 100, in connect
    raise ConnectionException(
utils.protocol.LSIS.exceptions.ConnectionException: LSIS_ Error: [Connection] Failed to connect to 192.168.0.198:2004

During handling of the above exception, another exception occurred:

Traceback (most recent call last):
  File "D:\project\projects\jais\py_backend\utils\logger.py", line 67, in wrapper
    return func(*args, **kwargs)
           ^^^^^^^^^^^^^^^^^^^^^
  File "D:\project/projects/jais/py_backend\LSISsocket\service.py", line 104, in tcp_client_servive
    updated_at=now
               ^^^
UnboundLocalError: cannot access local variable 'now' where it is not associated with a value
[2025-05-22 14:53:33] [INFO] try to connect LSIS client => 192.168.0.198:2004
[2025-05-22 14:53:34] [ERROR] tcp_client_servive : LSIS_ Error: [Connection] Failed to connect to 192.168.0.198:2004
[2025-05-22 14:53:34] [ERROR] 🚨 [ERROR] tcp_client_servive()에서 예외 발생 🚨
📌 파일: D:\project\projects\jais\py_backend\utils\logger.py, 라인: 67
📍 오류 메시지: cannot access local variable 'now' where it is not associated with a value
Traceback (most recent call last):
  File "D:\project\projects\jais\py_backend\utils\protocol\LSIS\client\tcp.py", line 83, in connect
    self.socket = socket.create_connection(
                  ^^^^^^^^^^^^^^^^^^^^^^^^^
  File "C:\Python\Python312\Lib\socket.py", line 865, in create_connection
    raise exceptions[0]
  File "C:\Python\Python312\Lib\socket.py", line 850, in create_connection
    sock.connect(sa)
TimeoutError: [WinError 10060] 연결된 구성원으로부터 응답이 없어 연결하지 못했거나, 호스트로부터 응답이 없어 연결이 끊어졌습니다

During handling of the above exception, another exception occurred:

Traceback (most recent call last):
  File "D:\project/projects/jais/py_backend\LSISsocket\service.py", line 32, in tcp_client_servive
    connect_sock.connect(retry_forever=False)
  File "D:\project\projects\jais\py_backend\utils\protocol\LSIS\client\tcp.py", line 100, in connect
    raise ConnectionException(
utils.protocol.LSIS.exceptions.ConnectionException: LSIS_ Error: [Connection] Failed to connect to 192.168.0.198:2004

During handling of the above exception, another exception occurred:

Traceback (most recent call last):
  File "D:\project\projects\jais\py_backend\utils\logger.py", line 67, in wrapper
    return func(*args, **kwargs)
           ^^^^^^^^^^^^^^^^^^^^^
  File "D:\project/projects/jais/py_backend\LSISsocket\service.py", line 104, in tcp_client_servive
    updated_at=now
               ^^^
UnboundLocalError: cannot access local variable 'now' where it is not associated with a value
[2025-05-22 14:53:38] [INFO] try to connect LSIS client => 192.168.0.198:2004
[2025-05-22 14:53:39] [ERROR] tcp_client_servive : LSIS_ Error: [Connection] Failed to connect to 192.168.0.198:2004
[2025-05-22 14:53:39] [ERROR] 🚨 [ERROR] tcp_client_servive()에서 예외 발생 🚨
📌 파일: D:\project\projects\jais\py_backend\utils\logger.py, 라인: 67
📍 오류 메시지: cannot access local variable 'now' where it is not associated with a value
Traceback (most recent call last):
  File "D:\project\projects\jais\py_backend\utils\protocol\LSIS\client\tcp.py", line 83, in connect
    self.socket = socket.create_connection(
                  ^^^^^^^^^^^^^^^^^^^^^^^^^
  File "C:\Python\Python312\Lib\socket.py", line 865, in create_connection
    raise exceptions[0]
  File "C:\Python\Python312\Lib\socket.py", line 850, in create_connection
    sock.connect(sa)
TimeoutError: [WinError 10060] 연결된 구성원으로부터 응답이 없어 연결하지 못했거나, 호스트로부터 응답이 없어 연결이 끊어졌습니다

During handling of the above exception, another exception occurred:

Traceback (most recent call last):
  File "D:\project/projects/jais/py_backend\LSISsocket\service.py", line 32, in tcp_client_servive
    connect_sock.connect(retry_forever=False)
  File "D:\project\projects\jais\py_backend\utils\protocol\LSIS\client\tcp.py", line 100, in connect
    raise ConnectionException(
utils.protocol.LSIS.exceptions.ConnectionException: LSIS_ Error: [Connection] Failed to connect to 192.168.0.198:2004

During handling of the above exception, another exception occurred:

Traceback (most recent call last):
  File "D:\project\projects\jais\py_backend\utils\logger.py", line 67, in wrapper
    return func(*args, **kwargs)
           ^^^^^^^^^^^^^^^^^^^^^
  File "D:\project/projects/jais/py_backend\LSISsocket\service.py", line 104, in tcp_client_servive
    updated_at=now
               ^^^
UnboundLocalError: cannot access local variable 'now' where it is not associated with a value
[2025-05-22 14:53:43] [INFO] try to connect LSIS client => 192.168.0.198:2004
[2025-05-22 14:53:44] [ERROR] tcp_client_servive : LSIS_ Error: [Connection] Failed to connect to 192.168.0.198:2004
[2025-05-22 14:53:44] [ERROR] 🚨 [ERROR] tcp_client_servive()에서 예외 발생 🚨
📌 파일: D:\project\projects\jais\py_backend\utils\logger.py, 라인: 67
📍 오류 메시지: cannot access local variable 'now' where it is not associated with a value
Traceback (most recent call last):
  File "D:\project\projects\jais\py_backend\utils\protocol\LSIS\client\tcp.py", line 83, in connect
    self.socket = socket.create_connection(
                  ^^^^^^^^^^^^^^^^^^^^^^^^^
  File "C:\Python\Python312\Lib\socket.py", line 865, in create_connection
    raise exceptions[0]
  File "C:\Python\Python312\Lib\socket.py", line 850, in create_connection
    sock.connect(sa)
TimeoutError: [WinError 10060] 연결된 구성원으로부터 응답이 없어 연결하지 못했거나, 호스트로부터 응답이 없어 연결이 끊어졌습니다

During handling of the above exception, another exception occurred:

Traceback (most recent call last):
  File "D:\project/projects/jais/py_backend\LSISsocket\service.py", line 32, in tcp_client_servive
    connect_sock.connect(retry_forever=False)
  File "D:\project\projects\jais\py_backend\utils\protocol\LSIS\client\tcp.py", line 100, in connect
    raise ConnectionException(
utils.protocol.LSIS.exceptions.ConnectionException: LSIS_ Error: [Connection] Failed to connect to 192.168.0.198:2004

During handling of the above exception, another exception occurred:

Traceback (most recent call last):
  File "D:\project\projects\jais\py_backend\utils\logger.py", line 67, in wrapper
    return func(*args, **kwargs)
           ^^^^^^^^^^^^^^^^^^^^^
  File "D:\project/projects/jais/py_backend\LSISsocket\service.py", line 104, in tcp_client_servive
    updated_at=now
               ^^^
UnboundLocalError: cannot access local variable 'now' where it is not associated with a value
[2025-05-22 14:53:48] [INFO] try to connect LSIS client => 192.168.0.198:2004
[2025-05-22 14:53:49] [ERROR] tcp_client_servive : LSIS_ Error: [Connection] Failed to connect to 192.168.0.198:2004
[2025-05-22 14:53:49] [ERROR] 🚨 [ERROR] tcp_client_servive()에서 예외 발생 🚨
📌 파일: D:\project\projects\jais\py_backend\utils\logger.py, 라인: 67
📍 오류 메시지: cannot access local variable 'now' where it is not associated with a value
Traceback (most recent call last):
  File "D:\project\projects\jais\py_backend\utils\protocol\LSIS\client\tcp.py", line 83, in connect
    self.socket = socket.create_connection(
                  ^^^^^^^^^^^^^^^^^^^^^^^^^
  File "C:\Python\Python312\Lib\socket.py", line 865, in create_connection
    raise exceptions[0]
  File "C:\Python\Python312\Lib\socket.py", line 850, in create_connection
    sock.connect(sa)
TimeoutError: [WinError 10060] 연결된 구성원으로부터 응답이 없어 연결하지 못했거나, 호스트로부터 응답이 없어 연결이 끊어졌습니다

During handling of the above exception, another exception occurred:

Traceback (most recent call last):
  File "D:\project/projects/jais/py_backend\LSISsocket\service.py", line 32, in tcp_client_servive
    connect_sock.connect(retry_forever=False)
  File "D:\project\projects\jais\py_backend\utils\protocol\LSIS\client\tcp.py", line 100, in connect
    raise ConnectionException(
utils.protocol.LSIS.exceptions.ConnectionException: LSIS_ Error: [Connection] Failed to connect to 192.168.0.198:2004

During handling of the above exception, another exception occurred:

Traceback (most recent call last):
  File "D:\project\projects\jais\py_backend\utils\logger.py", line 67, in wrapper
    return func(*args, **kwargs)
           ^^^^^^^^^^^^^^^^^^^^^
  File "D:\project/projects/jais/py_backend\LSISsocket\service.py", line 104, in tcp_client_servive
    updated_at=now
               ^^^
UnboundLocalError: cannot access local variable 'now' where it is not associated with a value
[2025-05-22 14:53:53] [INFO] try to connect LSIS client => 192.168.0.198:2004
[2025-05-22 14:53:54] [ERROR] tcp_client_servive : LSIS_ Error: [Connection] Failed to connect to 192.168.0.198:2004
[2025-05-22 14:53:54] [ERROR] 🚨 [ERROR] tcp_client_servive()에서 예외 발생 🚨
📌 파일: D:\project\projects\jais\py_backend\utils\logger.py, 라인: 67
📍 오류 메시지: cannot access local variable 'now' where it is not associated with a value
Traceback (most recent call last):
  File "D:\project\projects\jais\py_backend\utils\protocol\LSIS\client\tcp.py", line 83, in connect
    self.socket = socket.create_connection(
                  ^^^^^^^^^^^^^^^^^^^^^^^^^
  File "C:\Python\Python312\Lib\socket.py", line 865, in create_connection
    raise exceptions[0]
  File "C:\Python\Python312\Lib\socket.py", line 850, in create_connection
    sock.connect(sa)
TimeoutError: [WinError 10060] 연결된 구성원으로부터 응답이 없어 연결하지 못했거나, 호스트로부터 응답이 없어 연결이 끊어졌습니다

During handling of the above exception, another exception occurred:

Traceback (most recent call last):
  File "D:\project/projects/jais/py_backend\LSISsocket\service.py", line 32, in tcp_client_servive
    connect_sock.connect(retry_forever=False)
  File "D:\project\projects\jais\py_backend\utils\protocol\LSIS\client\tcp.py", line 100, in connect
    raise ConnectionException(
utils.protocol.LSIS.exceptions.ConnectionException: LSIS_ Error: [Connection] Failed to connect to 192.168.0.198:2004

During handling of the above exception, another exception occurred:

Traceback (most recent call last):
  File "D:\project\projects\jais\py_backend\utils\logger.py", line 67, in wrapper
    return func(*args, **kwargs)
           ^^^^^^^^^^^^^^^^^^^^^
  File "D:\project/projects/jais/py_backend\LSISsocket\service.py", line 104, in tcp_client_servive
    updated_at=now
               ^^^
UnboundLocalError: cannot access local variable 'now' where it is not associated with a value
[2025-05-22 14:53:58] [INFO] try to connect LSIS client => 192.168.0.198:2004
[2025-05-22 14:53:59] [ERROR] tcp_client_servive : LSIS_ Error: [Connection] Failed to connect to 192.168.0.198:2004
[2025-05-22 14:53:59] [ERROR] 🚨 [ERROR] tcp_client_servive()에서 예외 발생 🚨
📌 파일: D:\project\projects\jais\py_backend\utils\logger.py, 라인: 67
📍 오류 메시지: cannot access local variable 'now' where it is not associated with a value
Traceback (most recent call last):
  File "D:\project\projects\jais\py_backend\utils\protocol\LSIS\client\tcp.py", line 83, in connect
    self.socket = socket.create_connection(
                  ^^^^^^^^^^^^^^^^^^^^^^^^^
  File "C:\Python\Python312\Lib\socket.py", line 865, in create_connection
    raise exceptions[0]
  File "C:\Python\Python312\Lib\socket.py", line 850, in create_connection
    sock.connect(sa)
TimeoutError: [WinError 10060] 연결된 구성원으로부터 응답이 없어 연결하지 못했거나, 호스트로부터 응답이 없어 연결이 끊어졌습니다

During handling of the above exception, another exception occurred:

Traceback (most recent call last):
  File "D:\project/projects/jais/py_backend\LSISsocket\service.py", line 32, in tcp_client_servive
    connect_sock.connect(retry_forever=False)
  File "D:\project\projects\jais\py_backend\utils\protocol\LSIS\client\tcp.py", line 100, in connect
    raise ConnectionException(
utils.protocol.LSIS.exceptions.ConnectionException: LSIS_ Error: [Connection] Failed to connect to 192.168.0.198:2004

During handling of the above exception, another exception occurred:

Traceback (most recent call last):
  File "D:\project\projects\jais\py_backend\utils\logger.py", line 67, in wrapper
    return func(*args, **kwargs)
           ^^^^^^^^^^^^^^^^^^^^^
  File "D:\project/projects/jais/py_backend\LSISsocket\service.py", line 104, in tcp_client_servive
    updated_at=now
               ^^^
UnboundLocalError: cannot access local variable 'now' where it is not associated with a value
[2025-05-22 14:54:03] [INFO] try to connect LSIS client => 192.168.0.198:2004
[2025-05-22 14:54:04] [ERROR] tcp_client_servive : LSIS_ Error: [Connection] Failed to connect to 192.168.0.198:2004
[2025-05-22 14:54:04] [ERROR] 🚨 [ERROR] tcp_client_servive()에서 예외 발생 🚨
📌 파일: D:\project\projects\jais\py_backend\utils\logger.py, 라인: 67
📍 오류 메시지: cannot access local variable 'now' where it is not associated with a value
Traceback (most recent call last):
  File "D:\project\projects\jais\py_backend\utils\protocol\LSIS\client\tcp.py", line 83, in connect
    self.socket = socket.create_connection(
                  ^^^^^^^^^^^^^^^^^^^^^^^^^
  File "C:\Python\Python312\Lib\socket.py", line 865, in create_connection
    raise exceptions[0]
  File "C:\Python\Python312\Lib\socket.py", line 850, in create_connection
    sock.connect(sa)
TimeoutError: [WinError 10060] 연결된 구성원으로부터 응답이 없어 연결하지 못했거나, 호스트로부터 응답이 없어 연결이 끊어졌습니다

During handling of the above exception, another exception occurred:

Traceback (most recent call last):
  File "D:\project/projects/jais/py_backend\LSISsocket\service.py", line 32, in tcp_client_servive
    connect_sock.connect(retry_forever=False)
  File "D:\project\projects\jais\py_backend\utils\protocol\LSIS\client\tcp.py", line 100, in connect
    raise ConnectionException(
utils.protocol.LSIS.exceptions.ConnectionException: LSIS_ Error: [Connection] Failed to connect to 192.168.0.198:2004

During handling of the above exception, another exception occurred:

Traceback (most recent call last):
  File "D:\project\projects\jais\py_backend\utils\logger.py", line 67, in wrapper
    return func(*args, **kwargs)
           ^^^^^^^^^^^^^^^^^^^^^
  File "D:\project/projects/jais/py_backend\LSISsocket\service.py", line 104, in tcp_client_servive
    updated_at=now
               ^^^
UnboundLocalError: cannot access local variable 'now' where it is not associated with a value
[2025-05-22 14:54:08] [INFO] try to connect LSIS client => 192.168.0.198:2004
[2025-05-22 14:54:09] [ERROR] tcp_client_servive : LSIS_ Error: [Connection] Failed to connect to 192.168.0.198:2004
[2025-05-22 14:54:09] [ERROR] 🚨 [ERROR] tcp_client_servive()에서 예외 발생 🚨
📌 파일: D:\project\projects\jais\py_backend\utils\logger.py, 라인: 67
📍 오류 메시지: cannot access local variable 'now' where it is not associated with a value
Traceback (most recent call last):
  File "D:\project\projects\jais\py_backend\utils\protocol\LSIS\client\tcp.py", line 83, in connect
    self.socket = socket.create_connection(
                  ^^^^^^^^^^^^^^^^^^^^^^^^^
  File "C:\Python\Python312\Lib\socket.py", line 865, in create_connection
    raise exceptions[0]
  File "C:\Python\Python312\Lib\socket.py", line 850, in create_connection
    sock.connect(sa)
TimeoutError: [WinError 10060] 연결된 구성원으로부터 응답이 없어 연결하지 못했거나, 호스트로부터 응답이 없어 연결이 끊어졌습니다

During handling of the above exception, another exception occurred:

Traceback (most recent call last):
  File "D:\project/projects/jais/py_backend\LSISsocket\service.py", line 32, in tcp_client_servive
    connect_sock.connect(retry_forever=False)
  File "D:\project\projects\jais\py_backend\utils\protocol\LSIS\client\tcp.py", line 100, in connect
    raise ConnectionException(
utils.protocol.LSIS.exceptions.ConnectionException: LSIS_ Error: [Connection] Failed to connect to 192.168.0.198:2004

During handling of the above exception, another exception occurred:

Traceback (most recent call last):
  File "D:\project\projects\jais\py_backend\utils\logger.py", line 67, in wrapper
    return func(*args, **kwargs)
           ^^^^^^^^^^^^^^^^^^^^^
  File "D:\project/projects/jais/py_backend\LSISsocket\service.py", line 104, in tcp_client_servive
    updated_at=now
               ^^^
UnboundLocalError: cannot access local variable 'now' where it is not associated with a value
[2025-05-22 14:54:13] [INFO] try to connect LSIS client => 192.168.0.198:2004
[2025-05-22 14:54:14] [ERROR] tcp_client_servive : LSIS_ Error: [Connection] Failed to connect to 192.168.0.198:2004
[2025-05-22 14:54:14] [ERROR] 🚨 [ERROR] tcp_client_servive()에서 예외 발생 🚨
📌 파일: D:\project\projects\jais\py_backend\utils\logger.py, 라인: 67
📍 오류 메시지: cannot access local variable 'now' where it is not associated with a value
Traceback (most recent call last):
  File "D:\project\projects\jais\py_backend\utils\protocol\LSIS\client\tcp.py", line 83, in connect
    self.socket = socket.create_connection(
                  ^^^^^^^^^^^^^^^^^^^^^^^^^
  File "C:\Python\Python312\Lib\socket.py", line 865, in create_connection
    raise exceptions[0]
  File "C:\Python\Python312\Lib\socket.py", line 850, in create_connection
    sock.connect(sa)
TimeoutError: [WinError 10060] 연결된 구성원으로부터 응답이 없어 연결하지 못했거나, 호스트로부터 응답이 없어 연결이 끊어졌습니다

During handling of the above exception, another exception occurred:

Traceback (most recent call last):
  File "D:\project/projects/jais/py_backend\LSISsocket\service.py", line 32, in tcp_client_servive
    connect_sock.connect(retry_forever=False)
  File "D:\project\projects\jais\py_backend\utils\protocol\LSIS\client\tcp.py", line 100, in connect
    raise ConnectionException(
utils.protocol.LSIS.exceptions.ConnectionException: LSIS_ Error: [Connection] Failed to connect to 192.168.0.198:2004

During handling of the above exception, another exception occurred:

Traceback (most recent call last):
  File "D:\project\projects\jais\py_backend\utils\logger.py", line 67, in wrapper
    return func(*args, **kwargs)
           ^^^^^^^^^^^^^^^^^^^^^
  File "D:\project/projects/jais/py_backend\LSISsocket\service.py", line 104, in tcp_client_servive
    updated_at=now
               ^^^
UnboundLocalError: cannot access local variable 'now' where it is not associated with a value
[2025-05-22 14:54:18] [INFO] try to connect LSIS client => 192.168.0.198:2004
[2025-05-22 14:54:19] [ERROR] tcp_client_servive : LSIS_ Error: [Connection] Failed to connect to 192.168.0.198:2004
[2025-05-22 14:54:19] [ERROR] 🚨 [ERROR] tcp_client_servive()에서 예외 발생 🚨
📌 파일: D:\project\projects\jais\py_backend\utils\logger.py, 라인: 67
📍 오류 메시지: cannot access local variable 'now' where it is not associated with a value
Traceback (most recent call last):
  File "D:\project\projects\jais\py_backend\utils\protocol\LSIS\client\tcp.py", line 83, in connect
    self.socket = socket.create_connection(
                  ^^^^^^^^^^^^^^^^^^^^^^^^^
  File "C:\Python\Python312\Lib\socket.py", line 865, in create_connection
    raise exceptions[0]
  File "C:\Python\Python312\Lib\socket.py", line 850, in create_connection
    sock.connect(sa)
TimeoutError: [WinError 10060] 연결된 구성원으로부터 응답이 없어 연결하지 못했거나, 호스트로부터 응답이 없어 연결이 끊어졌습니다

During handling of the above exception, another exception occurred:

Traceback (most recent call last):
  File "D:\project/projects/jais/py_backend\LSISsocket\service.py", line 32, in tcp_client_servive
    connect_sock.connect(retry_forever=False)
  File "D:\project\projects\jais\py_backend\utils\protocol\LSIS\client\tcp.py", line 100, in connect
    raise ConnectionException(
utils.protocol.LSIS.exceptions.ConnectionException: LSIS_ Error: [Connection] Failed to connect to 192.168.0.198:2004

During handling of the above exception, another exception occurred:

Traceback (most recent call last):
  File "D:\project\projects\jais\py_backend\utils\logger.py", line 67, in wrapper
    return func(*args, **kwargs)
           ^^^^^^^^^^^^^^^^^^^^^
  File "D:\project/projects/jais/py_backend\LSISsocket\service.py", line 104, in tcp_client_servive
    updated_at=now
               ^^^
UnboundLocalError: cannot access local variable 'now' where it is not associated with a value
[2025-05-22 14:54:23] [INFO] try to connect LSIS client => 192.168.0.198:2004
[2025-05-22 14:54:24] [ERROR] tcp_client_servive : LSIS_ Error: [Connection] Failed to connect to 192.168.0.198:2004
[2025-05-22 14:54:24] [ERROR] 🚨 [ERROR] tcp_client_servive()에서 예외 발생 🚨
📌 파일: D:\project\projects\jais\py_backend\utils\logger.py, 라인: 67
📍 오류 메시지: cannot access local variable 'now' where it is not associated with a value
Traceback (most recent call last):
  File "D:\project\projects\jais\py_backend\utils\protocol\LSIS\client\tcp.py", line 83, in connect
    self.socket = socket.create_connection(
                  ^^^^^^^^^^^^^^^^^^^^^^^^^
  File "C:\Python\Python312\Lib\socket.py", line 865, in create_connection
    raise exceptions[0]
  File "C:\Python\Python312\Lib\socket.py", line 850, in create_connection
    sock.connect(sa)
TimeoutError: [WinError 10060] 연결된 구성원으로부터 응답이 없어 연결하지 못했거나, 호스트로부터 응답이 없어 연결이 끊어졌습니다

During handling of the above exception, another exception occurred:

Traceback (most recent call last):
  File "D:\project/projects/jais/py_backend\LSISsocket\service.py", line 32, in tcp_client_servive
    connect_sock.connect(retry_forever=False)
  File "D:\project\projects\jais\py_backend\utils\protocol\LSIS\client\tcp.py", line 100, in connect
    raise ConnectionException(
utils.protocol.LSIS.exceptions.ConnectionException: LSIS_ Error: [Connection] Failed to connect to 192.168.0.198:2004

During handling of the above exception, another exception occurred:

Traceback (most recent call last):
  File "D:\project\projects\jais\py_backend\utils\logger.py", line 67, in wrapper
    return func(*args, **kwargs)
           ^^^^^^^^^^^^^^^^^^^^^
  File "D:\project/projects/jais/py_backend\LSISsocket\service.py", line 104, in tcp_client_servive
    updated_at=now
               ^^^
UnboundLocalError: cannot access local variable 'now' where it is not associated with a value
[2025-05-22 14:54:28] [INFO] try to connect LSIS client => 192.168.0.198:2004
[2025-05-22 14:54:29] [ERROR] tcp_client_servive : LSIS_ Error: [Connection] Failed to connect to 192.168.0.198:2004
[2025-05-22 14:54:29] [ERROR] 🚨 [ERROR] tcp_client_servive()에서 예외 발생 🚨
📌 파일: D:\project\projects\jais\py_backend\utils\logger.py, 라인: 67
📍 오류 메시지: cannot access local variable 'now' where it is not associated with a value
Traceback (most recent call last):
  File "D:\project\projects\jais\py_backend\utils\protocol\LSIS\client\tcp.py", line 83, in connect
    self.socket = socket.create_connection(
                  ^^^^^^^^^^^^^^^^^^^^^^^^^
  File "C:\Python\Python312\Lib\socket.py", line 865, in create_connection
    raise exceptions[0]
  File "C:\Python\Python312\Lib\socket.py", line 850, in create_connection
    sock.connect(sa)
TimeoutError: [WinError 10060] 연결된 구성원으로부터 응답이 없어 연결하지 못했거나, 호스트로부터 응답이 없어 연결이 끊어졌습니다

During handling of the above exception, another exception occurred:

Traceback (most recent call last):
  File "D:\project/projects/jais/py_backend\LSISsocket\service.py", line 32, in tcp_client_servive
    connect_sock.connect(retry_forever=False)
  File "D:\project\projects\jais\py_backend\utils\protocol\LSIS\client\tcp.py", line 100, in connect
    raise ConnectionException(
utils.protocol.LSIS.exceptions.ConnectionException: LSIS_ Error: [Connection] Failed to connect to 192.168.0.198:2004

During handling of the above exception, another exception occurred:

Traceback (most recent call last):
  File "D:\project\projects\jais\py_backend\utils\logger.py", line 67, in wrapper
    return func(*args, **kwargs)
           ^^^^^^^^^^^^^^^^^^^^^
  File "D:\project/projects/jais/py_backend\LSISsocket\service.py", line 104, in tcp_client_servive
    updated_at=now
               ^^^
UnboundLocalError: cannot access local variable 'now' where it is not associated with a value
[2025-05-22 14:54:33] [INFO] try to connect LSIS client => 192.168.0.198:2004
[2025-05-22 14:54:34] [ERROR] tcp_client_servive : LSIS_ Error: [Connection] Failed to connect to 192.168.0.198:2004
[2025-05-22 14:54:34] [ERROR] 🚨 [ERROR] tcp_client_servive()에서 예외 발생 🚨
📌 파일: D:\project\projects\jais\py_backend\utils\logger.py, 라인: 67
📍 오류 메시지: cannot access local variable 'now' where it is not associated with a value
Traceback (most recent call last):
  File "D:\project\projects\jais\py_backend\utils\protocol\LSIS\client\tcp.py", line 83, in connect
    self.socket = socket.create_connection(
                  ^^^^^^^^^^^^^^^^^^^^^^^^^
  File "C:\Python\Python312\Lib\socket.py", line 865, in create_connection
    raise exceptions[0]
  File "C:\Python\Python312\Lib\socket.py", line 850, in create_connection
    sock.connect(sa)
TimeoutError: [WinError 10060] 연결된 구성원으로부터 응답이 없어 연결하지 못했거나, 호스트로부터 응답이 없어 연결이 끊어졌습니다

During handling of the above exception, another exception occurred:

Traceback (most recent call last):
  File "D:\project/projects/jais/py_backend\LSISsocket\service.py", line 32, in tcp_client_servive
    connect_sock.connect(retry_forever=False)
  File "D:\project\projects\jais\py_backend\utils\protocol\LSIS\client\tcp.py", line 100, in connect
    raise ConnectionException(
utils.protocol.LSIS.exceptions.ConnectionException: LSIS_ Error: [Connection] Failed to connect to 192.168.0.198:2004

During handling of the above exception, another exception occurred:

Traceback (most recent call last):
  File "D:\project\projects\jais\py_backend\utils\logger.py", line 67, in wrapper
    return func(*args, **kwargs)
           ^^^^^^^^^^^^^^^^^^^^^
  File "D:\project/projects/jais/py_backend\LSISsocket\service.py", line 104, in tcp_client_servive
    updated_at=now
               ^^^
UnboundLocalError: cannot access local variable 'now' where it is not associated with a value
[2025-05-22 14:54:39] [ERROR] tcp_client_servive : LSIS_ Error: [Connection] Failed to connect to 192.168.0.198:2004
[2025-05-22 14:54:39] [ERROR] 🚨 [ERROR] tcp_client_servive()에서 예외 발생 🚨
📌 파일: D:\project\projects\jais\py_backend\utils\logger.py, 라인: 67
📍 오류 메시지: cannot access local variable 'now' where it is not associated with a value
Traceback (most recent call last):
  File "D:\project\projects\jais\py_backend\utils\protocol\LSIS\client\tcp.py", line 83, in connect
    self.socket = socket.create_connection(
                  ^^^^^^^^^^^^^^^^^^^^^^^^^
  File "C:\Python\Python312\Lib\socket.py", line 865, in create_connection
    raise exceptions[0]
  File "C:\Python\Python312\Lib\socket.py", line 850, in create_connection
    sock.connect(sa)
TimeoutError: [WinError 10060] 연결된 구성원으로부터 응답이 없어 연결하지 못했거나, 호스트로부터 응답이 없어 연결이 끊어졌습니다

During handling of the above exception, another exception occurred:

Traceback (most recent call last):
  File "D:\project/projects/jais/py_backend\LSISsocket\service.py", line 32, in tcp_client_servive
    connect_sock.connect(retry_forever=False)
  File "D:\project\projects\jais\py_backend\utils\protocol\LSIS\client\tcp.py", line 100, in connect
    raise ConnectionException(
utils.protocol.LSIS.exceptions.ConnectionException: LSIS_ Error: [Connection] Failed to connect to 192.168.0.198:2004

During handling of the above exception, another exception occurred:

Traceback (most recent call last):
  File "D:\project\projects\jais\py_backend\utils\logger.py", line 67, in wrapper
    return func(*args, **kwargs)
           ^^^^^^^^^^^^^^^^^^^^^
  File "D:\project/projects/jais/py_backend\LSISsocket\service.py", line 104, in tcp_client_servive
    values=socketValue,
               ^^^
UnboundLocalError: cannot access local variable 'now' where it is not associated with a value
[2025-05-22 14:54:44] [ERROR] tcp_client_servive : LSIS_ Error: [Connection] Failed to connect to 192.168.0.198:2004
[2025-05-22 14:54:44] [ERROR] 🚨 [ERROR] tcp_client_servive()에서 예외 발생 🚨
📌 파일: D:\project\projects\jais\py_backend\utils\logger.py, 라인: 67
📍 오류 메시지: cannot access local variable 'now' where it is not associated with a value
Traceback (most recent call last):
  File "D:\project\projects\jais\py_backend\utils\protocol\LSIS\client\tcp.py", line 83, in connect
    self.socket = socket.create_connection(
                  ^^^^^^^^^^^^^^^^^^^^^^^^^
  File "C:\Python\Python312\Lib\socket.py", line 865, in create_connection
    raise exceptions[0]
  File "C:\Python\Python312\Lib\socket.py", line 850, in create_connection
    sock.connect(sa)
TimeoutError: [WinError 10060] 연결된 구성원으로부터 응답이 없어 연결하지 못했거나, 호스트로부터 응답이 없어 연결이 끊어졌습니다

During handling of the above exception, another exception occurred:

Traceback (most recent call last):
  File "D:\project/projects/jais/py_backend\LSISsocket\service.py", line 32, in tcp_client_servive
    connect_sock.connect(retry_forever=False)
  File "D:\project\projects\jais\py_backend\utils\protocol\LSIS\client\tcp.py", line 100, in connect
    raise ConnectionException(
utils.protocol.LSIS.exceptions.ConnectionException: LSIS_ Error: [Connection] Failed to connect to 192.168.0.198:2004

During handling of the above exception, another exception occurred:

Traceback (most recent call last):
  File "D:\project\projects\jais\py_backend\utils\logger.py", line 67, in wrapper
    return func(*args, **kwargs)
           ^^^^^^^^^^^^^^^^^^^^^
  File "D:\project/projects/jais/py_backend\LSISsocket\service.py", line 104, in tcp_client_servive
    values=socketValue,
               ^^^
UnboundLocalError: cannot access local variable 'now' where it is not associated with a value
[2025-05-22 14:54:49] [ERROR] tcp_client_servive : LSIS_ Error: [Connection] Failed to connect to 192.168.0.198:2004
[2025-05-22 14:54:49] [ERROR] 🚨 [ERROR] tcp_client_servive()에서 예외 발생 🚨
📌 파일: D:\project\projects\jais\py_backend\utils\logger.py, 라인: 67
📍 오류 메시지: cannot access local variable 'now' where it is not associated with a value
Traceback (most recent call last):
  File "D:\project\projects\jais\py_backend\utils\protocol\LSIS\client\tcp.py", line 83, in connect
    self.socket = socket.create_connection(
                  ^^^^^^^^^^^^^^^^^^^^^^^^^
  File "C:\Python\Python312\Lib\socket.py", line 865, in create_connection
    raise exceptions[0]
  File "C:\Python\Python312\Lib\socket.py", line 850, in create_connection
    sock.connect(sa)
TimeoutError: [WinError 10060] 연결된 구성원으로부터 응답이 없어 연결하지 못했거나, 호스트로부터 응답이 없어 연결이 끊어졌습니다

During handling of the above exception, another exception occurred:

Traceback (most recent call last):
  File "D:\project/projects/jais/py_backend\LSISsocket\service.py", line 32, in tcp_client_servive
    connect_sock.connect(retry_forever=False)
  File "D:\project\projects\jais\py_backend\utils\protocol\LSIS\client\tcp.py", line 100, in connect
    raise ConnectionException(
utils.protocol.LSIS.exceptions.ConnectionException: LSIS_ Error: [Connection] Failed to connect to 192.168.0.198:2004

During handling of the above exception, another exception occurred:

Traceback (most recent call last):
  File "D:\project\projects\jais\py_backend\utils\logger.py", line 67, in wrapper
    return func(*args, **kwargs)
           ^^^^^^^^^^^^^^^^^^^^^
  File "D:\project/projects/jais/py_backend\LSISsocket\service.py", line 104, in tcp_client_servive
    values=socketValue,
               ^^^
UnboundLocalError: cannot access local variable 'now' where it is not associated with a value
[2025-05-22 14:54:54] [ERROR] tcp_client_servive : LSIS_ Error: [Connection] Failed to connect to 192.168.0.198:2004
[2025-05-22 14:54:54] [ERROR] 🚨 [ERROR] tcp_client_servive()에서 예외 발생 🚨
📌 파일: D:\project\projects\jais\py_backend\utils\logger.py, 라인: 67
📍 오류 메시지: cannot access local variable 'now' where it is not associated with a value
Traceback (most recent call last):
  File "D:\project\projects\jais\py_backend\utils\protocol\LSIS\client\tcp.py", line 83, in connect
    self.socket = socket.create_connection(
                  ^^^^^^^^^^^^^^^^^^^^^^^^^
  File "C:\Python\Python312\Lib\socket.py", line 865, in create_connection
    raise exceptions[0]
  File "C:\Python\Python312\Lib\socket.py", line 850, in create_connection
    sock.connect(sa)
TimeoutError: [WinError 10060] 연결된 구성원으로부터 응답이 없어 연결하지 못했거나, 호스트로부터 응답이 없어 연결이 끊어졌습니다

During handling of the above exception, another exception occurred:

Traceback (most recent call last):
  File "D:\project/projects/jais/py_backend\LSISsocket\service.py", line 32, in tcp_client_servive
    connect_sock.connect(retry_forever=False)
  File "D:\project\projects\jais\py_backend\utils\protocol\LSIS\client\tcp.py", line 100, in connect
    raise ConnectionException(
utils.protocol.LSIS.exceptions.ConnectionException: LSIS_ Error: [Connection] Failed to connect to 192.168.0.198:2004

During handling of the above exception, another exception occurred:

Traceback (most recent call last):
  File "D:\project\projects\jais\py_backend\utils\logger.py", line 67, in wrapper
    return func(*args, **kwargs)
           ^^^^^^^^^^^^^^^^^^^^^
  File "D:\project/projects/jais/py_backend\LSISsocket\service.py", line 104, in tcp_client_servive
    values=socketValue,
               ^^^
UnboundLocalError: cannot access local variable 'now' where it is not associated with a value
[2025-05-22 14:55:00] [INFO] try to connect LSIS client => 192.168.0.198:2004
[2025-05-22 14:55:05] [INFO] try to connect LSIS client => 192.168.0.198:2004
[2025-05-22 14:55:10] [INFO] try to connect LSIS client => 192.168.0.198:2004
[2025-05-22 14:55:15] [INFO] try to connect LSIS client => 192.168.0.198:2004
[2025-05-22 14:55:21] [ERROR] tcp_client_servive : LSIS_ Error: [Connection] Failed to connect to 192.168.0.198:2004
[2025-05-22 14:55:26] [ERROR] tcp_client_servive : LSIS_ Error: [Connection] Failed to connect to 192.168.0.198:2004
[2025-05-22 14:55:31] [ERROR] tcp_client_servive : LSIS_ Error: [Connection] Failed to connect to 192.168.0.198:2004
[2025-05-22 14:55:36] [ERROR] tcp_client_servive : LSIS_ Error: [Connection] Failed to connect to 192.168.0.198:2004
[2025-05-22 14:55:46] [INFO] try to connect LSIS client => 192.168.0.198:2004
[2025-05-22 14:55:51] [INFO] try to connect LSIS client => 192.168.0.198:2004
[2025-05-22 14:55:56] [INFO] try to connect LSIS client => 192.168.0.198:2004
[2025-05-22 14:56:01] [INFO] try to connect LSIS client => 192.168.0.198:2004
[2025-05-22 14:56:06] [INFO] try to connect LSIS client => 192.168.0.198:2004
[2025-05-22 14:56:07] [ERROR] tcp_client_servive : LSIS_ Error: [Connection] Failed to connect to 192.168.0.198:2004
[2025-05-22 14:56:11] [INFO] try to connect LSIS client => 192.168.0.198:2004
[2025-05-22 14:56:12] [ERROR] tcp_client_servive : LSIS_ Error: [Connection] Failed to connect to 192.168.0.198:2004
[2025-05-22 14:56:16] [INFO] try to connect LSIS client => 192.168.0.198:2004
[2025-05-22 14:56:17] [ERROR] tcp_client_servive : LSIS_ Error: [Connection] Failed to connect to 192.168.0.198:2004
[2025-05-22 14:56:21] [INFO] try to connect LSIS client => 192.168.0.198:2004
[2025-05-22 14:56:22] [ERROR] tcp_client_servive : LSIS_ Error: [Connection] Failed to connect to 192.168.0.198:2004
[2025-05-22 14:56:26] [INFO] try to connect LSIS client => 192.168.0.198:2004
[2025-05-22 14:56:27] [ERROR] tcp_client_servive : LSIS_ Error: [Connection] Failed to connect to 192.168.0.198:2004
[2025-05-22 14:56:31] [INFO] try to connect LSIS client => 192.168.0.198:2004
[2025-05-22 14:56:32] [ERROR] tcp_client_servive : LSIS_ Error: [Connection] Failed to connect to 192.168.0.198:2004
[2025-05-22 14:56:36] [INFO] try to connect LSIS client => 192.168.0.198:2004
[2025-05-22 14:56:37] [ERROR] tcp_client_servive : LSIS_ Error: [Connection] Failed to connect to 192.168.0.198:2004
[2025-05-22 14:56:41] [INFO] try to connect LSIS client => 192.168.0.198:2004
[2025-05-22 14:56:42] [ERROR] tcp_client_servive : LSIS_ Error: [Connection] Failed to connect to 192.168.0.198:2004
[2025-05-22 14:56:46] [INFO] try to connect LSIS client => 192.168.0.198:2004
[2025-05-22 14:56:47] [ERROR] cancel to connect LSIS client => 192.168.0.198:2004
[2025-05-22 14:56:47] [ERROR] tcp_client_servive : LSIS_ Error: [Connection] Failed to connect to 192.168.0.198:2004
[2025-05-22 15:06:50] [INFO] try to connect LSIS client => 192.168.0.198:2004
[2025-05-22 15:21:49] [INFO] try to connect LSIS client => 192.168.0.198:2004
[2025-05-22 15:22:05] [INFO] try to connect LSIS client => 192.168.0.198:2004
[2025-05-22 15:22:49] [INFO] try to connect LSIS client => 192.168.0.198:2004
[2025-05-22 15:22:59] [INFO] try to connect LSIS client => 192.168.0.198:2004
[2025-05-22 15:24:16] [INFO] try to connect LSIS client => 192.168.0.198:2004
[2025-05-22 15:25:45] [INFO] try to connect LSIS client => 192.168.0.198:2004
[2025-05-22 15:26:19] [INFO] try to connect LSIS client => 192.168.0.198:2004
[2025-05-22 15:26:26] [INFO] try to connect LSIS client => 192.168.0.198:2004
[2025-05-22 15:27:00] [INFO] try to connect LSIS client => 192.168.0.198:2004
[2025-05-22 15:27:18] [INFO] try to connect LSIS client => 192.168.0.198:2004
[2025-05-22 15:28:17] [INFO] try to connect LSIS client => 192.168.0.198:2004
[2025-05-22 15:28:32] [INFO] try to connect LSIS client => 192.168.0.198:2004
[2025-05-22 15:28:37] [INFO] try to connect LSIS client => 192.168.0.198:2004
[2025-05-22 15:30:15] [INFO] try to connect LSIS client => 192.168.0.198:2004
[2025-05-22 15:30:45] [INFO] try to connect LSIS client => 192.168.0.198:2004
[2025-05-22 15:31:30] [INFO] try to connect LSIS client => 192.168.0.198:2004
[2025-05-22 15:32:13] [INFO] try to connect LSIS client => 192.168.0.198:2004
[2025-05-22 15:32:35] [INFO] try to connect LSIS client => 192.168.0.198:2004
[2025-05-22 15:32:52] [INFO] try to connect LSIS client => 192.168.0.198:2004
[2025-05-22 15:35:44] [INFO] try to connect LSIS client => 192.168.0.198:2004
[2025-05-22 15:36:29] [INFO] try to connect LSIS client => 192.168.0.198:2004
[2025-05-22 15:36:41] [INFO] try to connect LSIS client => 192.168.0.198:2004
[2025-05-22 15:38:50] [INFO] try to connect LSIS client => 192.168.0.198:2004
[2025-05-22 15:38:58] [INFO] try to connect LSIS client => 192.168.0.198:2004
[2025-05-22 15:39:30] [INFO] try to connect LSIS client => 192.168.0.198:2004
[2025-05-22 15:41:58] [INFO] try to connect LSIS client => 192.168.0.198:2004
[2025-05-22 15:42:17] [INFO] try to connect LSIS client => 192.168.0.198:2004
[2025-05-22 15:43:26] [INFO] try to connect LSIS client => 192.168.0.198:2004
[2025-05-22 15:44:18] [INFO] try to connect LSIS client => 192.168.0.198:2004
[2025-05-22 15:44:48] [INFO] try to connect LSIS client => 192.168.0.198:2004
[2025-05-22 15:45:19] [INFO] try to connect LSIS client => 192.168.0.198:2004
[2025-05-22 15:46:16] [INFO] try to connect LSIS client => 192.168.0.198:2004
[2025-05-22 15:47:14] [INFO] try to connect LSIS client => 192.168.0.198:2004
[2025-05-22 15:47:44] [INFO] try to connect LSIS client => 192.168.0.198:2004
[2025-05-22 15:47:59] [INFO] try to connect LSIS client => 192.168.0.198:2004
[2025-05-22 15:48:45] [INFO] try to connect LSIS client => 192.168.0.198:2004
[2025-05-22 15:48:53] [INFO] try to connect LSIS client => 192.168.0.198:2004
[2025-05-22 15:49:01] [INFO] try to connect LSIS client => 192.168.0.198:2004
[2025-05-22 15:49:52] [INFO] try to connect LSIS client => 192.168.0.198:2004
[2025-05-22 15:50:18] [INFO] try to connect LSIS client => 192.168.0.198:2004
[2025-05-22 15:50:26] [INFO] try to connect LSIS client => 192.168.0.198:2004
[2025-05-22 15:50:48] [INFO] try to connect LSIS client => 192.168.0.198:2004
[2025-05-22 15:51:39] [INFO] try to connect LSIS client => 192.168.0.198:2004
[2025-05-22 15:52:26] [INFO] try to connect LSIS client => 192.168.0.198:2004
[2025-05-22 15:52:34] [INFO] try to connect LSIS client => 192.168.0.198:2004
[2025-05-22 15:54:29] [INFO] try to connect LSIS client => 192.168.0.198:2004
[2025-05-22 15:54:39] [INFO] try to connect LSIS client => 192.168.0.198:2004
[2025-05-22 15:55:28] [INFO] try to connect LSIS client => 192.168.0.198:2004
[2025-05-22 15:56:00] [INFO] try to connect LSIS client => 192.168.0.198:2004
[2025-05-22 15:56:54] [INFO] try to connect LSIS client => 192.168.0.198:2004
[2025-05-22 15:57:22] [INFO] try to connect LSIS client => 192.168.0.198:2004
[2025-05-22 15:57:37] [INFO] try to connect LSIS client => 192.168.0.198:2004
[2025-05-22 15:58:01] [INFO] try to connect LSIS client => 192.168.0.198:2004
[2025-05-22 15:59:07] [INFO] try to connect LSIS client => 192.168.0.198:2004
[2025-05-22 15:59:33] [INFO] try to connect LSIS client => 192.168.0.198:2004
[2025-05-22 15:59:59] [INFO] try to connect LSIS client => 192.168.0.198:2004
[2025-05-22 16:00:53] [INFO] try to connect LSIS client => 192.168.0.198:2004
[2025-05-22 16:01:58] [INFO] try to connect LSIS client => 192.168.0.198:2004
[2025-05-22 16:02:22] [INFO] try to connect LSIS client => 192.168.0.198:2004
[2025-05-22 16:02:52] [INFO] try to connect LSIS client => 192.168.0.198:2004
[2025-05-22 16:03:24] [INFO] try to connect LSIS client => 192.168.0.198:2004
[2025-05-22 16:30:51] [INFO] try to connect LSIS client => 192.168.0.198:2004
[2025-05-22 16:32:11] [INFO] try to connect LSIS client => 192.168.0.198:2004
[2025-05-22 16:33:25] [INFO] try to connect LSIS client => 192.168.0.198:2004
[2025-05-22 16:33:51] [INFO] try to connect LSIS client => 192.168.0.198:2004
[2025-05-22 16:34:38] [INFO] try to connect LSIS client => 192.168.0.198:2004
[2025-05-22 16:35:40] [INFO] try to connect LSIS client => 192.168.0.198:2004
[2025-05-22 16:50:34] [INFO] try to connect LSIS client => 192.168.0.198:2004
